2025-02-20 09:30:46,400 root INFO: Getting started with the program.
2025-02-20 09:30:46,407 root INFO: Устаревшие лог-файлы удалены.
2025-02-20 09:30:46,409 root INFO: Data for connection are loaded
2025-02-20 09:30:46,887 root INFO: Database connection is completed successfully.
2025-02-20 09:30:46,888 root INFO: Sending a request for data in the range from 2023-04-01 00:00:00 to 2023-04-01 00:03:00.
2025-02-20 09:31:27,456 root INFO: The request was completed successfully.
2025-02-20 09:31:27,858 root INFO: Data is successfully loaded into the database.
2025-02-20 09:31:27,858 root INFO: All data for the selected period has been loaded into the database. The connection to the database was interrupted.
2025-02-20 09:31:32,375 root INFO: Getting started with the program.
2025-02-20 09:31:32,379 root INFO: Устаревшие лог-файлы удалены.
2025-02-20 09:31:32,381 root INFO: Data for connection are loaded
2025-02-20 09:31:32,483 root INFO: Database connection is completed successfully.
2025-02-20 09:31:32,484 root INFO: Sending a request for data in the range from 2023-04-01 00:00:00 to 2023-04-01 00:03:00.
2025-02-20 09:32:12,927 root INFO: The request was completed successfully.
2025-02-20 09:32:12,936 root INFO: Data is successfully loaded into the database.
2025-02-20 09:32:12,936 root INFO: All data for the selected period has been loaded into the database. The connection to the database was interrupted.
2025-02-20 09:44:34,913 root INFO: Getting started with the program.
2025-02-20 09:44:34,917 root INFO: Устаревшие лог-файлы удалены.
2025-02-20 09:44:34,918 root ERROR: Invalid values for period start and end: start = 2023-04-01 00:05:00, end = 2023-04-01 00:03:00.
Traceback (most recent call last):
  File "C:\Users\Владимир\PycharmProjects\pythonProject1\python_project_214.py", line 83, in <module>
    raise ValueError(f'Invalid values for period start and end: start = {START}, end = {END}.')
ValueError: Invalid values for period start and end: start = 2023-04-01 00:05:00, end = 2023-04-01 00:03:00.
2025-02-20 10:01:21,525 root INFO: Getting started with the program.
2025-02-20 10:01:21,529 root INFO: Устаревшие лог-файлы удалены.
2025-02-20 10:01:21,530 root INFO: Data for connection are loaded
2025-02-20 10:01:21,654 root INFO: Database connection is completed successfully.
2025-02-20 10:01:21,654 root INFO: Sending a request for data in the range from 2023-04-01 00:00:00 to 2023-04-01 00:03:00.
2025-02-20 10:02:01,262 root INFO: The request was completed successfully.
2025-02-20 10:02:01,262 root ERROR: unsupported operand type(s) for +=: 'int' and 'ellipsis'
Traceback (most recent call last):
  File "C:\Users\Владимир\PycharmProjects\pythonProject1\python_project_214.py", line 140, in <module>
    n_submit += 1 if attempt_type == 'submit' else ...
TypeError: unsupported operand type(s) for +=: 'int' and 'ellipsis'
2025-02-20 10:06:17,669 root INFO: Getting started with the program.
2025-02-20 10:06:17,673 root INFO: Устаревшие лог-файлы удалены.
2025-02-20 10:06:17,674 root INFO: Data for connection are loaded
2025-02-20 10:06:17,771 root INFO: Database connection is completed successfully.
2025-02-20 10:06:17,771 root INFO: Sending a request for data in the range from 2023-04-01 00:00:00 to 2023-04-01 00:03:00.
2025-02-20 10:06:58,984 root INFO: The request was completed successfully.
2025-02-20 10:06:58,984 root ERROR: unsupported operand type(s) for +=: 'int' and 'ellipsis'
Traceback (most recent call last):
  File "C:\Users\Владимир\PycharmProjects\pythonProject1\python_project_214.py", line 140, in <module>
    n_submit += 1 if attempt_type == 'submit' else ...
TypeError: unsupported operand type(s) for +=: 'int' and 'ellipsis'
2025-02-20 10:07:47,903 root INFO: Getting started with the program.
2025-02-20 10:07:47,907 root INFO: Устаревшие лог-файлы удалены.
2025-02-20 10:07:47,908 root INFO: Data for connection are loaded
2025-02-20 10:07:48,020 root INFO: Database connection is completed successfully.
2025-02-20 10:07:48,020 root INFO: Sending a request for data in the range from 2023-04-01 00:00:00 to 2023-04-01 00:03:00.
2025-02-20 10:08:27,190 root INFO: The request was completed successfully.
2025-02-20 10:08:27,249 root INFO: Data is successfully loaded into the database.
2025-02-20 10:08:27,249 root INFO: All data for the selected period has been loaded into the database. The connection to the database was interrupted.
2025-02-20 10:09:31,023 root INFO: Getting started with the program.
2025-02-20 10:09:31,025 root INFO: Устаревшие лог-файлы удалены.
2025-02-20 10:09:31,026 root INFO: Data for connection are loaded
2025-02-20 10:09:31,112 root INFO: Database connection is completed successfully.
2025-02-20 10:09:31,113 root INFO: Sending a request for data in the range from 2023-04-01 00:00:00 to 2023-04-01 00:15:00.
2025-02-20 10:10:17,842 root INFO: The request was completed successfully.
2025-02-20 10:10:18,279 root INFO: Data is successfully loaded into the database.
2025-02-20 10:10:18,280 root INFO: All data for the selected period has been loaded into the database. The connection to the database was interrupted.
2025-02-20 10:24:23,412 root INFO: Getting started with the program.
2025-02-20 10:24:23,416 root INFO: Устаревшие лог-файлы удалены.
2025-02-20 10:24:23,417 root INFO: Data for connection are loaded
2025-02-20 10:24:23,523 root INFO: Database connection is completed successfully.
2025-02-20 10:24:23,523 root INFO: Sending a request for data in the range from 2023-04-01 00:00:00 to 2023-04-01 00:28:00.
2025-02-20 10:25:07,795 root INFO: The request was completed successfully.
2025-02-20 10:25:07,906 root INFO: Data is successfully loaded into the database.
2025-02-20 10:25:07,906 root INFO: All data for the selected period has been loaded into the database. The connection to the database was interrupted.
2025-02-20 17:30:43,553 root INFO: Getting started with the program.
2025-02-20 17:30:43,560 root INFO: Устаревшие лог-файлы удалены.
2025-02-20 17:30:43,561 root INFO: Data for connection are loaded
2025-02-20 17:30:44,076 root INFO: Database connection is completed successfully.
2025-02-20 17:30:44,076 root INFO: Sending a request for data in the range from 2023-04-01 00:00:00 to 2023-04-01 00:28:00.
2025-02-20 17:31:28,366 root INFO: The request was completed successfully.
2025-02-20 17:31:28,993 root INFO: Data is successfully loaded into the database.
2025-02-20 17:31:28,994 root INFO: All data for the selected period has been loaded into the database. The connection to the database was interrupted.
2025-02-20 17:46:46,909 root INFO: Getting started with the program.
2025-02-20 17:46:46,915 root INFO: Устаревшие лог-файлы удалены.
2025-02-20 17:46:46,916 root INFO: Data for connection are loaded
2025-02-20 17:46:47,408 root INFO: Database connection is completed successfully.
2025-02-20 17:46:47,408 root INFO: Sending a request for data in the range from 2023-04-01 00:00:00 to 2023-04-01 00:28:00.
2025-02-20 17:47:30,579 root INFO: The request was completed successfully.
2025-02-20 17:47:30,957 root INFO: Data is successfully loaded into the database.
2025-02-20 17:47:30,957 root INFO: All data for the selected period has been loaded into the database. The connection to the database was interrupted.
2025-02-20 18:09:10,712 root INFO: Getting started with the program.
2025-02-20 18:09:10,718 root INFO: Устаревшие лог-файлы удалены.
2025-02-20 18:09:10,720 root INFO: Data for connection are loaded
2025-02-20 18:09:11,349 root INFO: Database connection is completed successfully.
2025-02-20 18:09:11,349 root INFO: Sending a request for data in the range from 2023-04-01 00:00:00 to 2023-04-01 00:28:00.
2025-02-20 18:10:27,774 root INFO: The request was completed successfully.
2025-02-20 18:10:28,150 root INFO: Data is successfully loaded into the database.
2025-02-20 18:10:28,151 root INFO: All data for the selected period has been loaded into the database. The connection to the database was interrupted.
2025-02-20 18:30:06,204 root INFO: Getting started with the program.
2025-02-20 18:30:06,210 root INFO: Устаревшие лог-файлы удалены.
2025-02-20 18:30:06,212 root INFO: Data for connection are loaded
2025-02-20 18:30:06,438 root INFO: Database connection is completed successfully.
2025-02-20 18:30:06,439 root INFO: Sending a request for data in the range from 2023-04-01 00:00:00 to 2023-04-01 00:28:00.
2025-02-20 18:30:53,160 root INFO: The request was completed successfully.
2025-02-20 19:04:28,882 root INFO: Getting started with the program.
2025-02-20 19:04:28,887 root INFO: Устаревшие лог-файлы удалены.
2025-02-20 19:04:28,888 root INFO: Data for connection are loaded
2025-02-20 19:04:29,383 root INFO: Database connection is completed successfully.
2025-02-20 19:04:29,383 root INFO: Sending a request for data in the range from 2023-04-01 00:00:00 to 2023-04-01 00:02:00.
2025-02-20 19:04:31,506 root ERROR: HTTPSConnectionPool(host='b2b.itresume.ru', port=443): Max retries exceeded with url: /api/statistics?client=Skillfactory&client_key=M2MGWS&start=2023-04-01+00%3A00%3A00.000000&end=2023-04-01+00%3A02%3A00.000000 (Caused by NameResolutionError("<urllib3.connection.HTTPSConnection object at 0x00000174E4C66350>: Failed to resolve 'b2b.itresume.ru' ([Errno 11002] getaddrinfo failed)"))
Traceback (most recent call last):
  File "C:\Users\Владимир\AppData\Local\Programs\Python\Python313\Lib\site-packages\urllib3\connection.py", line 198, in _new_conn
    sock = connection.create_connection(
        (self._dns_host, self.port),
    ...<2 lines>...
        socket_options=self.socket_options,
    )
  File "C:\Users\Владимир\AppData\Local\Programs\Python\Python313\Lib\site-packages\urllib3\util\connection.py", line 60, in create_connection
    for res in socket.getaddrinfo(host, port, family, socket.SOCK_STREAM):
               ~~~~~~~~~~~~~~~~~~^^^^^^^^^^^^^^^^^^^^^^^^^^^^^^^^^^^^^^^^
  File "C:\Users\Владимир\AppData\Local\Programs\Python\Python313\Lib\socket.py", line 977, in getaddrinfo
    for res in _socket.getaddrinfo(host, port, family, type, proto, flags):
               ~~~~~~~~~~~~~~~~~~~^^^^^^^^^^^^^^^^^^^^^^^^^^^^^^^^^^^^^^^^
socket.gaierror: [Errno 11002] getaddrinfo failed

The above exception was the direct cause of the following exception:

Traceback (most recent call last):
  File "C:\Users\Владимир\AppData\Local\Programs\Python\Python313\Lib\site-packages\urllib3\connectionpool.py", line 787, in urlopen
    response = self._make_request(
        conn,
    ...<10 lines>...
        **response_kw,
    )
  File "C:\Users\Владимир\AppData\Local\Programs\Python\Python313\Lib\site-packages\urllib3\connectionpool.py", line 488, in _make_request
    raise new_e
  File "C:\Users\Владимир\AppData\Local\Programs\Python\Python313\Lib\site-packages\urllib3\connectionpool.py", line 464, in _make_request
    self._validate_conn(conn)
    ~~~~~~~~~~~~~~~~~~~^^^^^^
  File "C:\Users\Владимир\AppData\Local\Programs\Python\Python313\Lib\site-packages\urllib3\connectionpool.py", line 1093, in _validate_conn
    conn.connect()
    ~~~~~~~~~~~~^^
  File "C:\Users\Владимир\AppData\Local\Programs\Python\Python313\Lib\site-packages\urllib3\connection.py", line 704, in connect
    self.sock = sock = self._new_conn()
                       ~~~~~~~~~~~~~~^^
  File "C:\Users\Владимир\AppData\Local\Programs\Python\Python313\Lib\site-packages\urllib3\connection.py", line 205, in _new_conn
    raise NameResolutionError(self.host, self, e) from e
urllib3.exceptions.NameResolutionError: <urllib3.connection.HTTPSConnection object at 0x00000174E4C66350>: Failed to resolve 'b2b.itresume.ru' ([Errno 11002] getaddrinfo failed)

The above exception was the direct cause of the following exception:

Traceback (most recent call last):
  File "C:\Users\Владимир\AppData\Local\Programs\Python\Python313\Lib\site-packages\requests\adapters.py", line 667, in send
    resp = conn.urlopen(
        method=request.method,
    ...<9 lines>...
        chunked=chunked,
    )
  File "C:\Users\Владимир\AppData\Local\Programs\Python\Python313\Lib\site-packages\urllib3\connectionpool.py", line 841, in urlopen
    retries = retries.increment(
        method, url, error=new_e, _pool=self, _stacktrace=sys.exc_info()[2]
    )
  File "C:\Users\Владимир\AppData\Local\Programs\Python\Python313\Lib\site-packages\urllib3\util\retry.py", line 519, in increment
    raise MaxRetryError(_pool, url, reason) from reason  # type: ignore[arg-type]
    ^^^^^^^^^^^^^^^^^^^^^^^^^^^^^^^^^^^^^^^^^^^^^^^^^^^
urllib3.exceptions.MaxRetryError: HTTPSConnectionPool(host='b2b.itresume.ru', port=443): Max retries exceeded with url: /api/statistics?client=Skillfactory&client_key=M2MGWS&start=2023-04-01+00%3A00%3A00.000000&end=2023-04-01+00%3A02%3A00.000000 (Caused by NameResolutionError("<urllib3.connection.HTTPSConnection object at 0x00000174E4C66350>: Failed to resolve 'b2b.itresume.ru' ([Errno 11002] getaddrinfo failed)"))

During handling of the above exception, another exception occurred:

Traceback (most recent call last):
  File "C:\Users\Владимир\PycharmProjects\pythonProject1\python_project_214.py", line 133, in <module>
    responce = requests.get(API_URL, params=params)
  File "C:\Users\Владимир\AppData\Local\Programs\Python\Python313\Lib\site-packages\requests\api.py", line 73, in get
    return request("get", url, params=params, **kwargs)
  File "C:\Users\Владимир\AppData\Local\Programs\Python\Python313\Lib\site-packages\requests\api.py", line 59, in request
    return session.request(method=method, url=url, **kwargs)
           ~~~~~~~~~~~~~~~^^^^^^^^^^^^^^^^^^^^^^^^^^^^^^^^^^
  File "C:\Users\Владимир\AppData\Local\Programs\Python\Python313\Lib\site-packages\requests\sessions.py", line 589, in request
    resp = self.send(prep, **send_kwargs)
  File "C:\Users\Владимир\AppData\Local\Programs\Python\Python313\Lib\site-packages\requests\sessions.py", line 703, in send
    r = adapter.send(request, **kwargs)
  File "C:\Users\Владимир\AppData\Local\Programs\Python\Python313\Lib\site-packages\requests\adapters.py", line 700, in send
    raise ConnectionError(e, request=request)
requests.exceptions.ConnectionError: HTTPSConnectionPool(host='b2b.itresume.ru', port=443): Max retries exceeded with url: /api/statistics?client=Skillfactory&client_key=M2MGWS&start=2023-04-01+00%3A00%3A00.000000&end=2023-04-01+00%3A02%3A00.000000 (Caused by NameResolutionError("<urllib3.connection.HTTPSConnection object at 0x00000174E4C66350>: Failed to resolve 'b2b.itresume.ru' ([Errno 11002] getaddrinfo failed)"))
2025-02-20 20:27:48,072 root INFO: Getting started with the program.
2025-02-20 20:27:48,078 root INFO: Устаревшие лог-файлы удалены.
2025-02-20 20:27:48,079 root INFO: Data for connection are loaded
2025-02-20 20:27:48,683 root INFO: Database connection is completed successfully.
2025-02-20 20:27:48,683 root INFO: Sending a request for data in the range from 2023-04-01 00:00:00 to 2023-04-01 00:02:00.
2025-02-20 20:28:31,230 root INFO: The request was completed successfully.
2025-02-20 20:28:32,008 root INFO: Data is successfully loaded into the database.
2025-02-20 20:28:32,009 root INFO: All data for the selected period has been loaded into the database. The connection to the database was interrupted.
2025-02-20 20:28:32,009 root ERROR: float division by zero
Traceback (most recent call last):
  File "C:\Users\Владимир\PycharmProjects\pythonProject1\python_project_214.py", line 188, in <module>
    success_rate = round(100. * n_correct_per_id_uniq / n_submit_per_id_uniq, 2)
                         ~~~~~~~~~~~~~~~~~~~~~~~~~~~~~^~~~~~~~~~~~~~~~~~~~~~
ZeroDivisionError: float division by zero
2025-02-20 20:36:48,808 root INFO: Getting started with the program.
2025-02-20 20:36:48,813 root INFO: Устаревшие лог-файлы удалены.
2025-02-20 20:36:48,814 root INFO: Data for connection are loaded
2025-02-20 20:36:48,920 root INFO: Database connection is completed successfully.
2025-02-20 20:36:48,920 root INFO: Sending a request for data in the range from 2023-04-01 00:00:00 to 2023-04-01 00:02:00.
2025-02-20 20:37:36,817 root INFO: The request was completed successfully.
2025-02-20 20:37:36,824 root INFO: Data is successfully loaded into the database.
2025-02-20 20:37:36,824 root INFO: All data for the selected period has been loaded into the database. The connection to the database was interrupted.
2025-02-20 20:37:38,357 root ERROR: 'Worksheet' object has no attribute 'append'
Traceback (most recent call last):
  File "C:\Users\Владимир\PycharmProjects\pythonProject1\python_project_214.py", line 213, in <module>
    worksheet.append('A2:J2', [START, END, n_id_uniq, n_all, n_submit, n_correct, success_rate,
    ^^^^^^^^^^^^^^^^
AttributeError: 'Worksheet' object has no attribute 'append'
2025-02-20 20:44:46,212 root INFO: Getting started with the program.
2025-02-20 20:44:46,218 root INFO: Устаревшие лог-файлы удалены.
2025-02-20 20:44:46,219 root INFO: Data for connection are loaded
2025-02-20 20:44:46,780 root INFO: Database connection is completed successfully.
2025-02-20 20:44:46,780 root INFO: Sending a request for data in the range from 2023-04-01 00:00:00 to 2023-04-01 00:02:00.
2025-02-20 20:45:39,636 root INFO: The request was completed successfully.
2025-02-20 20:45:40,179 root INFO: Data is successfully loaded into the database.
2025-02-20 20:45:40,179 root INFO: All data for the selected period has been loaded into the database. The connection to the database was interrupted.
2025-02-20 20:45:43,015 root ERROR: APIError: [400]: Invalid value at 'data.values[0]' (type.googleapis.com/google.protobuf.ListValue), "A2:J2"
Invalid value at 'value_input_option' (type.googleapis.com/google.apps.sheets.v4.ValueInputOption), "2023-04-01 00:00:00"
Invalid value at 'value_input_option' (type.googleapis.com/google.apps.sheets.v4.ValueInputOption), "2023-04-01 00:02:00"
Invalid value at 'value_input_option' (type.googleapis.com/google.apps.sheets.v4.ValueInputOption), "60.0"
Invalid value at 'value_input_option' (type.googleapis.com/google.apps.sheets.v4.ValueInputOption), "0.0"
Invalid value at 'value_input_option' (type.googleapis.com/google.apps.sheets.v4.ValueInputOption), "0.0"
Invalid value at 'value_input_option' (type.googleapis.com/google.apps.sheets.v4.ValueInputOption), "2.0"
Invalid value at 'value_input_option' (type.googleapis.com/google.apps.sheets.v4.ValueInputOption), "0.0"
Invalid value at 'value_input_option' (type.googleapis.com/google.apps.sheets.v4.ValueInputOption), "0.0"
Traceback (most recent call last):
  File "C:\Users\Владимир\PycharmProjects\pythonProject1\python_project_214.py", line 214, in <module>
    worksheet.append_row('A2:J2', [START, END, n_id_uniq, n_all, n_submit, n_correct, success_rate,
    ~~~~~~~~~~~~~~~~~~~~^^^^^^^^^^^^^^^^^^^^^^^^^^^^^^^^^^^^^^^^^^^^^^^^^^^^^^^^^^^^^^^^^^^^^^^^^^^
                               n_all_per_hour, n_submit_per_hour, n_correct_per_hour,
                               ^^^^^^^^^^^^^^^^^^^^^^^^^^^^^^^^^^^^^^^^^^^^^^^^^^^^^^
                               n_all_per_id_uniq, n_submit_per_id_uniq, n_correct_per_id_uniq])
                               ^^^^^^^^^^^^^^^^^^^^^^^^^^^^^^^^^^^^^^^^^^^^^^^^^^^^^^^^^^^^^^^^
  File "C:\Users\Владимир\AppData\Local\Programs\Python\Python313\Lib\site-packages\gspread\worksheet.py", line 1806, in append_row
    return self.append_rows(
           ~~~~~~~~~~~~~~~~^
        [values],
        ^^^^^^^^^
    ...<3 lines>...
        include_values_in_response=include_values_in_response,
        ^^^^^^^^^^^^^^^^^^^^^^^^^^^^^^^^^^^^^^^^^^^^^^^^^^^^^^
    )
    ^
  File "C:\Users\Владимир\AppData\Local\Programs\Python\Python313\Lib\site-packages\gspread\worksheet.py", line 1856, in append_rows
    res = self.client.values_append(self.spreadsheet_id, range_label, params, body)
  File "C:\Users\Владимир\AppData\Local\Programs\Python\Python313\Lib\site-packages\gspread\http_client.py", line 191, in values_append
    r = self.request("post", url, params=params, json=body)
  File "C:\Users\Владимир\AppData\Local\Programs\Python\Python313\Lib\site-packages\gspread\http_client.py", line 128, in request
    raise APIError(response)
gspread.exceptions.APIError: APIError: [400]: Invalid value at 'data.values[0]' (type.googleapis.com/google.protobuf.ListValue), "A2:J2"
Invalid value at 'value_input_option' (type.googleapis.com/google.apps.sheets.v4.ValueInputOption), "2023-04-01 00:00:00"
Invalid value at 'value_input_option' (type.googleapis.com/google.apps.sheets.v4.ValueInputOption), "2023-04-01 00:02:00"
Invalid value at 'value_input_option' (type.googleapis.com/google.apps.sheets.v4.ValueInputOption), "60.0"
Invalid value at 'value_input_option' (type.googleapis.com/google.apps.sheets.v4.ValueInputOption), "0.0"
Invalid value at 'value_input_option' (type.googleapis.com/google.apps.sheets.v4.ValueInputOption), "0.0"
Invalid value at 'value_input_option' (type.googleapis.com/google.apps.sheets.v4.ValueInputOption), "2.0"
Invalid value at 'value_input_option' (type.googleapis.com/google.apps.sheets.v4.ValueInputOption), "0.0"
Invalid value at 'value_input_option' (type.googleapis.com/google.apps.sheets.v4.ValueInputOption), "0.0"
2025-02-20 21:01:36,231 root INFO: Getting started with the program.
2025-02-20 21:01:36,236 root INFO: Устаревшие лог-файлы удалены.
2025-02-20 21:01:36,237 root INFO: Data for connection are loaded
2025-02-20 21:01:36,780 root INFO: Database connection is completed successfully.
2025-02-20 21:01:36,780 root INFO: Sending a request for data in the range from 2023-04-01 00:00:00 to 2023-04-01 00:02:00.
2025-02-20 21:02:25,162 root INFO: The request was completed successfully.
2025-02-20 21:02:25,591 root INFO: Data is successfully loaded into the database.
2025-02-20 21:02:25,592 root INFO: All data for the selected period has been loaded into the database. The connection to the database was interrupted.
2025-02-20 21:02:26,756 root ERROR: 'Spreadsheet' object has no attribute 'Results'
Traceback (most recent call last):
  File "C:\Users\Владимир\PycharmProjects\pythonProject1\python_project_214.py", line 209, in <module>
    sheet = client.open("project214_result").Results
            ^^^^^^^^^^^^^^^^^^^^^^^^^^^^^^^^^^^^^^^^
AttributeError: 'Spreadsheet' object has no attribute 'Results'
2025-02-20 21:03:41,599 root INFO: Getting started with the program.
2025-02-20 21:03:41,604 root INFO: Устаревшие лог-файлы удалены.
2025-02-20 21:03:41,605 root INFO: Data for connection are loaded
2025-02-20 21:03:41,698 root INFO: Database connection is completed successfully.
2025-02-20 21:03:41,698 root INFO: Sending a request for data in the range from 2023-04-01 00:00:00 to 2023-04-01 00:02:00.
2025-02-20 21:04:29,313 root INFO: The request was completed successfully.
2025-02-20 21:04:29,336 root INFO: Data is successfully loaded into the database.
2025-02-20 21:04:29,336 root INFO: All data for the selected period has been loaded into the database. The connection to the database was interrupted.
2025-02-20 21:04:30,551 root ERROR: Object of type datetime is not JSON serializable
Traceback (most recent call last):
  File "C:\Users\Владимир\PycharmProjects\pythonProject1\python_project_214.py", line 214, in <module>
    sheet.append_row([START, END, n_id_uniq, n_all, n_submit, n_correct, success_rate,
    ~~~~~~~~~~~~~~~~^^^^^^^^^^^^^^^^^^^^^^^^^^^^^^^^^^^^^^^^^^^^^^^^^^^^^^^^^^^^^^^^^^
                               n_all_per_hour, n_submit_per_hour, n_correct_per_hour,
                               ^^^^^^^^^^^^^^^^^^^^^^^^^^^^^^^^^^^^^^^^^^^^^^^^^^^^^^
                               n_all_per_id_uniq, n_submit_per_id_uniq, n_correct_per_id_uniq])
                               ^^^^^^^^^^^^^^^^^^^^^^^^^^^^^^^^^^^^^^^^^^^^^^^^^^^^^^^^^^^^^^^^
  File "C:\Users\Владимир\AppData\Local\Programs\Python\Python313\Lib\site-packages\gspread\worksheet.py", line 1806, in append_row
    return self.append_rows(
           ~~~~~~~~~~~~~~~~^
        [values],
        ^^^^^^^^^
    ...<3 lines>...
        include_values_in_response=include_values_in_response,
        ^^^^^^^^^^^^^^^^^^^^^^^^^^^^^^^^^^^^^^^^^^^^^^^^^^^^^^
    )
    ^
  File "C:\Users\Владимир\AppData\Local\Programs\Python\Python313\Lib\site-packages\gspread\worksheet.py", line 1856, in append_rows
    res = self.client.values_append(self.spreadsheet_id, range_label, params, body)
  File "C:\Users\Владимир\AppData\Local\Programs\Python\Python313\Lib\site-packages\gspread\http_client.py", line 191, in values_append
    r = self.request("post", url, params=params, json=body)
  File "C:\Users\Владимир\AppData\Local\Programs\Python\Python313\Lib\site-packages\gspread\http_client.py", line 114, in request
    response = self.session.request(
        method=method,
    ...<6 lines>...
        timeout=self.timeout,
    )
  File "C:\Users\Владимир\AppData\Local\Programs\Python\Python313\Lib\site-packages\google\auth\transport\requests.py", line 537, in request
    response = super(AuthorizedSession, self).request(
        method,
    ...<4 lines>...
        **kwargs
    )
  File "C:\Users\Владимир\AppData\Local\Programs\Python\Python313\Lib\site-packages\requests\sessions.py", line 575, in request
    prep = self.prepare_request(req)
  File "C:\Users\Владимир\AppData\Local\Programs\Python\Python313\Lib\site-packages\requests\sessions.py", line 484, in prepare_request
    p.prepare(
    ~~~~~~~~~^
        method=request.method.upper(),
        ^^^^^^^^^^^^^^^^^^^^^^^^^^^^^^
    ...<10 lines>...
        hooks=merge_hooks(request.hooks, self.hooks),
        ^^^^^^^^^^^^^^^^^^^^^^^^^^^^^^^^^^^^^^^^^^^^^
    )
    ^
  File "C:\Users\Владимир\AppData\Local\Programs\Python\Python313\Lib\site-packages\requests\models.py", line 370, in prepare
    self.prepare_body(data, files, json)
    ~~~~~~~~~~~~~~~~~^^^^^^^^^^^^^^^^^^^
  File "C:\Users\Владимир\AppData\Local\Programs\Python\Python313\Lib\site-packages\requests\models.py", line 510, in prepare_body
    body = complexjson.dumps(json, allow_nan=False)
  File "C:\Users\Владимир\AppData\Local\Programs\Python\Python313\Lib\json\__init__.py", line 238, in dumps
    **kw).encode(obj)
          ~~~~~~^^^^^
  File "C:\Users\Владимир\AppData\Local\Programs\Python\Python313\Lib\json\encoder.py", line 200, in encode
    chunks = self.iterencode(o, _one_shot=True)
  File "C:\Users\Владимир\AppData\Local\Programs\Python\Python313\Lib\json\encoder.py", line 261, in iterencode
    return _iterencode(o, 0)
  File "C:\Users\Владимир\AppData\Local\Programs\Python\Python313\Lib\json\encoder.py", line 180, in default
    raise TypeError(f'Object of type {o.__class__.__name__} '
                    f'is not JSON serializable')
TypeError: Object of type datetime is not JSON serializable
2025-02-20 21:18:00,098 root INFO: Getting started with the program.
2025-02-20 21:18:00,103 root INFO: Устаревшие лог-файлы удалены.
2025-02-20 21:18:00,104 root INFO: Data for connection are loaded
2025-02-20 21:18:00,619 root INFO: Database connection is completed successfully.
2025-02-20 21:18:00,619 root INFO: Sending a request for data in the range from 2023-04-01 00:00:00 to 2023-04-01 00:02:00.
2025-02-20 21:18:45,594 root INFO: The request was completed successfully.
2025-02-20 21:18:46,110 root INFO: Data is successfully loaded into the database.
2025-02-20 21:18:46,111 root INFO: All data for the selected period has been loaded into the database. The connection to the database was interrupted.
2025-02-20 21:22:37,264 root INFO: Getting started with the program.
2025-02-20 21:22:37,268 root INFO: Устаревшие лог-файлы удалены.
2025-02-20 21:22:37,269 root INFO: Data for connection are loaded
2025-02-20 21:22:37,350 root INFO: Database connection is completed successfully.
2025-02-20 21:22:37,350 root INFO: Sending a request for data in the range from 2023-04-01 00:00:00 to 2023-04-01 00:02:00.
2025-02-20 21:23:19,496 root INFO: The request was completed successfully.
2025-02-20 21:23:19,513 root INFO: Data is successfully loaded into the database.
2025-02-20 21:23:19,513 root INFO: All data for the selected period has been loaded into the database. The connection to the database was interrupted.
